<?xml version="1.0" ?>
<sdf version="1.8">
    <model name='vehicle_blue' canonical_link='chassis'>
        <!--chassis-->
        <link name='chassis'>
            <pose relative_to='__model__'>0.0 0 0.2 0 0 0</pose>
            <sensor name="imu_sensor" type="imu">
                <always_on>1</always_on>
                <update_rate>1</update_rate>
                <visualize>true</visualize>
                <topic>imu</topic>
            </sensor>
            <visual name='visual'>
                <geometry>
                    <mesh>
                        <uri>package://robot_description/description/meshes</uri>
                        <scale>0.58 0.58 0.58</scale>
                    </mesh>
                </geometry>
                <!--Color of the link-->
                <material>
                    <ambient>0.0 0.0 1.0 1</ambient>
                    <diffuse>0.0 0.0 1.0 1</diffuse>
                    <specular>0.0 0.0 1.0 1</specular>
                </material>
            </visual>
            <collision name='collision'>
                <geometry>
                    <mesh>
                        <uri>package://robot_description/description/meshes</uri>
                        <scale>0.58 0.58 0.58</scale>
                    </mesh>
                </geometry>
            </collision>
        
        <!-- WHEELS  -->
        <!--rear Left wheel-->
        <link name='rear_left_wheel'>
            <pose relative_to="chassis">-0.6 0.42 0 -1.5707 0 0</pose> <!--angles are in radian-->
            <inertial>
                <mass>7</mass>
                <inertia>
                    <ixx>0.086858</ixx>
                    <ixy>0</ixy>
                    <ixz>0</ixz>
                    <iyy>0.086858</iyy>
                    <iyz>0</iyz>
                    <izz>0.14</izz>
                </inertia>
            </inertial>
            <visual name='visual'>
                <geometry>
                    <cylinder>
                        <radius>0.2</radius>
                        <length>0.17</length>
                    </cylinder>
                </geometry>
                <material>
                    <ambient>0.0 0.0 0.0 1</ambient>
                    <diffuse>0.0 0.0 0.0 1</diffuse>
                    <specular>0.0 0.0 0.0 1</specular>
                </material>
            </visual>
            <collision name='collision'>
                <geometry>
                    <cylinder>
                        <radius>0.2</radius>
                        <length>0.17</length>
                    </cylinder>
                </geometry>
            </collision>
        </link>

        <!--The same as left wheel but with different position-->
        <link name='rear_right_wheel'>
            <pose relative_to="chassis">-0.6 -0.42 0 -1.5707 0 0</pose> <!--angles are in radian-->
            <inertial>
                <mass>7</mass>
                <inertia>
                    <ixx>0.086858</ixx>
                    <ixy>0</ixy>
                    <ixz>0</ixz>
                    <iyy>0.086858</iyy>
                    <iyz>0</iyz>
                    <izz>0.14</izz>
                </inertia>
            </inertial>
            <visual name='visual'>
                <geometry>
                    <cylinder>
                        <radius>0.2</radius>
                        <length>0.17</length>
                    </cylinder>
                </geometry>
                <material>
                    <ambient>0.0 0.0 0.0 1</ambient>
                    <diffuse>0.0 0.0 0.0 1</diffuse>
                    <specular>0.0 0.0 0.0 1</specular>
                </material>
            </visual>
            <collision name='collision'>
                <geometry>
                    <cylinder>
                        <radius>0.2</radius>
                        <length>0.17</length>
                    </cylinder>
                </geometry>
            </collision>
        </link>

        <!--front Left wheel-->
        <link name='front_left_wheel'>
            <pose relative_to="chassis">0.6 0.45 0 -1.5707 0 0</pose> <!--angles are in radian-->
            <inertial>
                <mass>5</mass>
                <inertia>
                    <ixx>0.057042</ixx>
                    <ixy>0</ixy>
                    <ixz>0</ixz>
                    <iyy>0.057042</iyy>
                    <iyz>0</iyz>
                    <izz>0.1</izz>
                </inertia>
            </inertial>
            <visual name='visual'>
                <geometry>
                    <cylinder>
                        <radius>0.2</radius>
                        <length>0.13</length>
                    </cylinder>
                </geometry>
                <material>
                    <ambient>0.0 0.0 0.0 1</ambient>
                    <diffuse>0.0 0.0 0.0 1</diffuse>
                    <specular>0.0 0.0 0.0 1</specular>
                </material>
            </visual>
            <collision name='collision'>
                <geometry>
                    <cylinder>
                        <radius>0.2</radius>
                        <length>0.13</length>
                    </cylinder>
                </geometry>
            </collision>
        </link>

        <!--front Left wheel-->
        <link name='front_right_wheel'>
            <pose relative_to="chassis">0.6 -0.45 0 -1.5707 0 0</pose> <!--angles are in radian-->
            <inertial>
                <mass>5</mass>
                <inertia>
                    <ixx>0.057042</ixx>
                    <ixy>0</ixy>
                    <ixz>0</ixz>
                    <iyy>0.057042</iyy>
                    <iyz>0</iyz>
                    <izz>0.1</izz>
                </inertia>
            </inertial>
            <visual name='visual'>
                <geometry>
                    <cylinder>
                        <radius>0.2</radius>
                        <length>0.13</length>
                    </cylinder>
                </geometry>
                <material>
                    <ambient>0.0 0.0 0.0 1</ambient>
                    <diffuse>0.0 0.0 0.0 1</diffuse>
                    <specular>0.0 0.0 0.0 1</specular>
                </material>
            </visual>
            <collision name='collision'>
                <geometry>
                    <cylinder>
                        <radius>0.2</radius>
                        <length>0.13</length>
                    </cylinder>
                </geometry>
            </collision>
        </link>
        
        
        <!-- - - - - - - - - - - - - - - - - LINKAGE - - - - - - - -  - - - - - - - - - - -->
        <!--front left wheel steering link-->
        <link name='front_left_steering_link'>
            <pose relative_to='front_left_wheel'/>
            <inertial>
                <mass>0.5</mass>
                <inertia>
                    <ixx>0.015299999999999999</ixx>
                    <iyy>0.025000000000000001</iyy>
                    <izz>0.015299999999999999</izz>
                    <ixy>0</ixy>
                    <ixz>0</ixz>
                    <iyz>0</iyz>
                </inertia>
                <pose>0 0 0 0 -0 0</pose>
                </inertial>
                <enable_wind>false</enable_wind>
        </link>

        <!--front right wheel link-->
        <link name='front_right_steering_link'>
            <pose relative_to='front_right_wheel'/>
            <inertial>
                <mass>0.5</mass>
                <inertia>
                    <ixx>0.015299999999999999</ixx>
                    <iyy>0.025000000000000001</iyy>
                    <izz>0.015299999999999999</izz>
                    <ixy>0</ixy>
                    <ixz>0</ixz>
                    <iyz>0</iyz>
                </inertia>
                <pose>0 0 0 0 -0 0</pose>
                </inertial>
                <enable_wind>false</enable_wind>
        </link>

        <!--front left steering joint-->
        <joint name='front_left_steering_joint' type='revolute'>
            <parent>chassis</parent>
            <child>front_left_steering_link</child>
            <axis>
                <xyz expressed_in='__model__'>0 0 1</xyz> <!-- z-axis for steering -->
                <limit>
                    <lower>-1.79769e+308</lower>    <!--negative infinity-->
                    <upper>1.79769e+308</upper>     <!--positive infinity-->
                </limit>
            </axis>
        </joint>

        <!--front right steering joint-->
        <joint name='front_right_steering_joint' type='revolute'>
            <parent>chassis</parent>
            <child>front_right_steering_link</child>
            <axis>
                <xyz expressed_in='__model__'>0 0 1</xyz> <!-- z-axis for steering -->
                <limit>
                    <lower>-1.79769e+308</lower>    <!--negative infinity-->
                    <upper>1.79769e+308</upper>     <!--positive infinity-->
                </limit>
            </axis>
        </joint>
        
        <!-- - - - - - - - - - - - - -DEFINING JOINTS - - - - - - - - - - - - - - - - - -->
        <!--rear left wheel joint-->
        <joint name='rear_left_wheel_joint' type='revolute'>
            <pose relative_to='rear_left_wheel'/>
            <parent>chassis</parent>
            <child>rear_left_wheel</child>
            <axis>
                <xyz expressed_in='__model__'>0 1 0</xyz> <!--can be descired to any frame or even arbitrary frames-->
                <limit>
                    <lower>-1.79769e+308</lower>    <!--negative infinity-->
                    <upper>1.79769e+308</upper>     <!--positive infinity-->
                </limit>
            </axis>
        </joint>

        <!--rear right wheel joint-->
        <joint name='rear_right_wheel_joint' type='revolute'>
            <pose relative_to='rear_right_wheel'/>
            <parent>chassis</parent>
            <child>rear_right_wheel</child>
            <axis>
                <xyz expressed_in='__model__'>0 1 0</xyz>
                <limit>
                    <lower>-1.79769e+308</lower>    <!--negative infinity-->
                    <upper>1.79769e+308</upper>     <!--positive infinity-->
                </limit>
            </axis>
        </joint>

        <!--front left wheel joint-->
        <joint name='front_left_wheel_joint' type='revolute'>
            <pose relative_to='front_left_wheel'/>
            <parent>front_left_steering_link</parent>
            <child>front_left_wheel</child>
            <axis>
                <xyz expressed_in='__model__'>0 1 0</xyz> <!--can be descired to any frame or even arbitrary frames-->
                <limit>
                    <lower>-1.79769e+308</lower>    <!--negative infinity-->
                    <upper>1.79769e+308</upper>     <!--positive infinity-->
                </limit>
            </axis>
        </joint>

        <!--front right wheel joint-->
        <joint name='front_right_wheel_joint' type='revolute'>
            <pose relative_to='front_right_wheel'/>
            <parent>front_right_steering_link</parent>
            <child>front_right_wheel</child>
            <axis>
                <xyz expressed_in='__model__'>0 1 0</xyz> <!--can be descired to any frame or even arbitrary frames-->
                <limit>
                    <lower>-1.79769e+308</lower>    <!--negative infinity-->
                    <upper>1.79769e+308</upper>     <!--positive infinity-->
                </limit>
            </axis>
        </joint>
        <plugin name='ignition::gazebo::systems::AckermannSteering' filename='ignition-gazebo-ackermann-steering-system'>
            <topic>/cmd_vel</topic>
            <left_joint>front_left_wheel_joint</left_joint>
            <left_joint>rear_left_wheel_joint</left_joint>
            <right_joint>front_right_wheel_joint</right_joint>
            <right_joint>rear_right_wheel_joint</right_joint>
            <left_steering_joint>front_left_steering_joint</left_steering_joint>
            <right_steering_joint>front_right_steering_joint</right_steering_joint>
            <kingpin_width>0.75</kingpin_width>
            <steering_limit>0.5</steering_limit>
            <wheel_base>1.25</wheel_base>
            <wheel_separation>0.9</wheel_separation>
            <wheel_radius>0.2</wheel_radius>
            <min_velocity>-10</min_velocity>
            <max_velocity>100</max_velocity>
            <min_acceleration>-30</min_acceleration>
            <max_acceleration>30</max_acceleration>
        </plugin>
        <static>false</static>
        <self_collide>false</self_collide>    
    </model>
</sdf>
